Workbook

Sheet diccionario_
A1: instructor_ | B1: rut_instructor | C1: codigo_perfil_cv | D1: firma_ | E1: marcas | F1: tipo | G1: modelo
A3: Marcelo Camilo Barrera Acevedo | B3: 13.364.290-0 | C3: P-8549-2359-004-V01 | D3: Marcelo Barrera A. | E3: MERCEDES BENZ | F3: BUS 1 PISO | G3: O500 RS - OC500 RF
A4: Daniel Rodrigo Carvajal Bucarey | B4: 10.528.715-1 | C4: P-8549-2359-004-V01 | D4: Daniel Carvajal B. | E4: ZHONG TONG | F4: BUS 1 1/2 PISO | G4: O500 RS-D
A5: Fernando Rodrigo Maza Roman | B5: 12.476.744-k | C5: P-8549-2359-004-V01 | D5: Fernando Maza R. | E5: SCANIA | F5: BUS 2 PISOS | G5: SPRINTER 315 – 415 – 515 – 517 4X2
A6: Gilberto Leonardo Urtubia Carvajal | B6: 9.249.626-0 | C6: P-8549-2359-004-V01 | D6: Gilerto Urtubia C. | E6: VOLVO | F6: TAXIBUS | G6: SPRINTER 516 4x4
A7: Milla Miranda Guillermo Andres | B7: 15.325.100-2 | C7: P-8549-2359-004-V01 | D7: Guillermo Milla M. | E7: VOLARE | F7: MINIBUS | G7: LO915 - LO916
E8: IVECO | G8: F310 HB
E9: MAXUS | G9: K 360 IB
E10: YUTONG | G10: K 410CB
G11: K 440 IB
G12: K 400 IB
G13: B 420R - B 430R
G14: B 450R
G15: DAILY 50 - 170 4X2
G16: ZT LCK6129EV
G17: V8L 4X4
G18: E DELIBERY 9
G19: C9 ZK6709H

Sheet dot_
A1: Nombre Completo | B1: Número de Documento | C1: Cargo | D1: Nombre Área
A2: Abarca Vivar Juan Agustin | B2: 8.448.934-4 | C2: CONDUCTOR DE BUS AREA INDUSTRIAL | D2: AURA - DAND
A3: Abarca Vivar Juan Agustin | B3: 8.448.934-4 | C3: CONDUCTOR DE BUS | D3: CODELCO VP ANDINA 2022
A4: Abello Rojas Paola Soledad | B4: 12.575.276-4 | C4: CONDUCTOR DE FURGON | D4: SERVICIO CODELCO DMH
A5: Acevedo González Manuel Guillermo | B5: 7.614.405-2 | C5: CONDUCTOR DE BUS | D5: SIERRA GORDA - OPERACION
A6: Acevedo Jofré Jorge Andrés | B6: 11.478.221-1 | C6: CONDUCTOR DE BUS | D6: SYNCORE - TALABRE
A7: Acevedo Mardones William Mario | B7: 10.160.908-1 | C7: CONDUCTOR DE BUS | D7: VALPARAISO
A8: Acosta Salazar Oberney | B8: 26.607.465-4 | C8: CONDUCTOR DE BUS | D8: ALTO NORTE
A9: Acuña Henriquez Milton Andre | B9: 14.305.012-2 | C9: CONDUCTOR DE MINIBUS AREA INDUSTRIAL | D9: CODELCO ANDINA 2022
A10: Adaro Leal Franco Ignacio | B10: 18.006.078-2 | C10: COORDINADOR DE SERVICIOS | D10: NEWREST COLLAHUASI
A11: Agosin Lara David Adolfo | B11: 12.643.301-8 | C11: CONDUCTOR DE BUS | D11: FLIX VIÑA DEL MAR
A12: Aguayo Salinas Miguel Angel | B12: 8.805.198-k | C12: CONDUCTOR DE BUS | D12: JM SERVICIOS ESPECIALES
... A1653: Zuvic Caro Javier Mauricio | B1653: 10.516.045-3 | C1653: CONDUCTOR DE BUS | D1653: SIERRA GORDA - OPERACION

Sheet firmas
D2: Firmado digitalmente por: Marcelo Barrera A.
D3: Firmado digitalmente por: Daniel Carvajal B.
D4: Firmado digitalmente por: Fernando Maza R.
D5: Firmado digitalmente por: Gilberto Urtubia C.

Sheet form
A1: instructor_ | B1: rut_instructor | C1: codigo_perfil_cv | D1: fecha | E1: hora | F1: trabajador_ | G1: rut_trabajador | H1: marca_ | I1: tipo_1 | J1: modelo_1 | K1: modelo_2 | L1: modelo_3 | M1: modelos_todos | N1: evaluacion_
B2: =IF(Tabla4[[#This Row],[instructor_]]="","",_xlfn.XLOOKUP(Tabla4[[#This Row],[instructor_]],diccionario_!$A$1:$A$13,diccionario_!$B$1:$B$13,,0)) | C2: =IF(Tabla4[[#This Row],[instructor_]]="","",_xlfn.XLOOKUP(Tabla4[[#This Row],[instructor_]],diccionario_!$A$1:$A$13,diccionario_!$C$1:$C$13,,0)) | G2: =IF(Tabla4[[#This Row],[trabajador_]]="","",_xlfn.XLOOKUP(Tabla4[[#This Row],[trabajador_]],Tabla2[Nombre Completo],Tabla2[Número de Documento],,0)) | M2: =_xlfn.TEXTJOIN(" - ",TRUE,Tabla4[[#This Row],[modelo_1]],Tabla4[[#This Row],[modelo_2]],Tabla4[[#This Row],[modelo_3]])
B3: =IF(Tabla4[[#This Row],[instructor_]]="","",_xlfn.XLOOKUP(Tabla4[[#This Row],[instructor_]],diccionario_!$A$1:$A$13,diccionario_!$B$1:$B$13,,0)) | C3: =IF(Tabla4[[#This Row],[instructor_]]="","",_xlfn.XLOOKUP(Tabla4[[#This Row],[instructor_]],diccionario_!$A$1:$A$13,diccionario_!$C$1:$C$13,,0)) | G3: =IF(Tabla4[[#This Row],[trabajador_]]="","",_xlfn.XLOOKUP(Tabla4[[#This Row],[trabajador_]],Tabla2[Nombre Completo],Tabla2[Número de Documento],,0)) | M3: =_xlfn.TEXTJOIN(" - ",TRUE,Tabla4[[#This Row],[modelo_1]],Tabla4[[#This Row],[modelo_2]],Tabla4[[#This Row],[modelo_3]])
B4: =IF(Tabla4[[#This Row],[instructor_]]="","",_xlfn.XLOOKUP(Tabla4[[#This Row],[instructor_]],diccionario_!$A$1:$A$13,diccionario_!$B$1:$B$13,,0)) | C4: =IF(Tabla4[[#This Row],[instructor_]]="","",_xlfn.XLOOKUP(Tabla4[[#This Row],[instructor_]],diccionario_!$A$1:$A$13,diccionario_!$C$1:$C$13,,0)) | G4: =IF(Tabla4[[#This Row],[trabajador_]]="","",_xlfn.XLOOKUP(Tabla4[[#This Row],[trabajador_]],Tabla2[Nombre Completo],Tabla2[Número de Documento],,0)) | M4: =_xlfn.TEXTJOIN(" - ",TRUE,Tabla4[[#This Row],[modelo_1]],Tabla4[[#This Row],[modelo_2]],Tabla4[[#This Row],[modelo_3]])
B5: =IF(Tabla4[[#This Row],[instructor_]]="","",_xlfn.XLOOKUP(Tabla4[[#This Row],[instructor_]],diccionario_!$A$1:$A$13,diccionario_!$B$1:$B$13,,0)) | C5: =IF(Tabla4[[#This Row],[instructor_]]="","",_xlfn.XLOOKUP(Tabla4[[#This Row],[instructor_]],diccionario_!$A$1:$A$13,diccionario_!$C$1:$C$13,,0)) | G5: =IF(Tabla4[[#This Row],[trabajador_]]="","",_xlfn.XLOOKUP(Tabla4[[#This Row],[trabajador_]],Tabla2[Nombre Completo],Tabla2[Número de Documento],,0)) | M5: =_xlfn.TEXTJOIN(" - ",TRUE,Tabla4[[#This Row],[modelo_1]],Tabla4[[#This Row],[modelo_2]],Tabla4[[#This Row],[modelo_3]])
B6: =IF(Tabla4[[#This Row],[instructor_]]="","",_xlfn.XLOOKUP(Tabla4[[#This Row],[instructor_]],diccionario_!$A$1:$A$13,diccionario_!$B$1:$B$13,,0)) | C6: =IF(Tabla4[[#This Row],[instructor_]]="","",_xlfn.XLOOKUP(Tabla4[[#This Row],[instructor_]],diccionario_!$A$1:$A$13,diccionario_!$C$1:$C$13,,0)) | G6: =IF(Tabla4[[#This Row],[trabajador_]]="","",_xlfn.XLOOKUP(Tabla4[[#This Row],[trabajador_]],Tabla2[Nombre Completo],Tabla2[Número de Documento],,0)) | M6: =_xlfn.TEXTJOIN(" - ",TRUE,Tabla4[[#This Row],[modelo_1]],Tabla4[[#This Row],[modelo_2]],Tabla4[[#This Row],[modelo_3]])
B7: =IF(Tabla4[[#This Row],[instructor_]]="","",_xlfn.XLOOKUP(Tabla4[[#This Row],[instructor_]],diccionario_!$A$1:$A$13,diccionario_!$B$1:$B$13,,0)) | C7: =IF(Tabla4[[#This Row],[instructor_]]="","",_xlfn.XLOOKUP(Tabla4[[#This Row],[instructor_]],diccionario_!$A$1:$A$13,diccionario_!$C$1:$C$13,,0)) | G7: =IF(Tabla4[[#This Row],[trabajador_]]="","",_xlfn.XLOOKUP(Tabla4[[#This Row],[trabajador_]],Tabla2[Nombre Completo],Tabla2[Número de Documento],,0)) | M7: =_xlfn.TEXTJOIN(" - ",TRUE,Tabla4[[#This Row],[modelo_1]],Tabla4[[#This Row],[modelo_2]],Tabla4[[#This Row],[modelo_3]])
B8: =IF(Tabla4[[#This Row],[instructor_]]="","",_xlfn.XLOOKUP(Tabla4[[#This Row],[instructor_]],diccionario_!$A$1:$A$13,diccionario_!$B$1:$B$13,,0)) | C8: =IF(Tabla4[[#This Row],[instructor_]]="","",_xlfn.XLOOKUP(Tabla4[[#This Row],[instructor_]],diccionario_!$A$1:$A$13,diccionario_!$C$1:$C$13,,0)) | G8: =IF(Tabla4[[#This Row],[trabajador_]]="","",_xlfn.XLOOKUP(Tabla4[[#This Row],[trabajador_]],Tabla2[Nombre Completo],Tabla2[Número de Documento],,0)) | M8: =_xlfn.TEXTJOIN(" - ",TRUE,Tabla4[[#This Row],[modelo_1]],Tabla4[[#This Row],[modelo_2]],Tabla4[[#This Row],[modelo_3]])
B9: =IF(Tabla4[[#This Row],[instructor_]]="","",_xlfn.XLOOKUP(Tabla4[[#This Row],[instructor_]],diccionario_!$A$1:$A$13,diccionario_!$B$1:$B$13,,0)) | C9: =IF(Tabla4[[#This Row],[instructor_]]="","",_xlfn.XLOOKUP(Tabla4[[#This Row],[instructor_]],diccionario_!$A$1:$A$13,diccionario_!$C$1:$C$13,,0)) | G9: =IF(Tabla4[[#This Row],[trabajador_]]="","",_xlfn.XLOOKUP(Tabla4[[#This Row],[trabajador_]],Tabla2[Nombre Completo],Tabla2[Número de Documento],,0)) | M9: =_xlfn.TEXTJOIN(" - ",TRUE,Tabla4[[#This Row],[modelo_1]],Tabla4[[#This Row],[modelo_2]],Tabla4[[#This Row],[modelo_3]])
B10: =IF(Tabla4[[#This Row],[instructor_]]="","",_xlfn.XLOOKUP(Tabla4[[#This Row],[instructor_]],diccionario_!$A$1:$A$13,diccionario_!$B$1:$B$13,,0)) | C10: =IF(Tabla4[[#This Row],[instructor_]]="","",_xlfn.XLOOKUP(Tabla4[[#This Row],[instructor_]],diccionario_!$A$1:$A$13,diccionario_!$C$1:$C$13,,0)) | G10: =IF(Tabla4[[#This Row],[trabajador_]]="","",_xlfn.XLOOKUP(Tabla4[[#This Row],[trabajador_]],Tabla2[Nombre Completo],Tabla2[Número de Documento],,0)) | M10: =_xlfn.TEXTJOIN(" - ",TRUE,Tabla4[[#This Row],[modelo_1]],Tabla4[[#This Row],[modelo_2]],Tabla4[[#This Row],[modelo_3]])
B11: =IF(Tabla4[[#This Row],[instructor_]]="","",_xlfn.XLOOKUP(Tabla4[[#This Row],[instructor_]],diccionario_!$A$1:$A$13,diccionario_!$B$1:$B$13,,0)) | C11: =IF(Tabla4[[#This Row],[instructor_]]="","",_xlfn.XLOOKUP(Tabla4[[#This Row],[instructor_]],diccionario_!$A$1:$A$13,diccionario_!$C$1:$C$13,,0)) | G11: =IF(Tabla4[[#This Row],[trabajador_]]="","",_xlfn.XLOOKUP(Tabla4[[#This Row],[trabajador_]],Tabla2[Nombre Completo],Tabla2[Número de Documento],,0)) | M11: =_xlfn.TEXTJOIN(" - ",TRUE,Tabla4[[#This Row],[modelo_1]],Tabla4[[#This Row],[modelo_2]],Tabla4[[#This Row],[modelo_3]])
B12: =IF(Tabla4[[#This Row],[instructor_]]="","",_xlfn.XLOOKUP(Tabla4[[#This Row],[instructor_]],diccionario_!$A$1:$A$13,diccionario_!$B$1:$B$13,,0)) | C12: =IF(Tabla4[[#This Row],[instructor_]]="","",_xlfn.XLOOKUP(Tabla4[[#This Row],[instructor_]],diccionario_!$A$1:$A$13,diccionario_!$C$1:$C$13,,0)) | G12: =IF(Tabla4[[#This Row],[trabajador_]]="","",_xlfn.XLOOKUP(Tabla4[[#This Row],[trabajador_]],Tabla2[Nombre Completo],Tabla2[Número de Documento],,0)) | M12: =_xlfn.TEXTJOIN(" - ",TRUE,Tabla4[[#This Row],[modelo_1]],Tabla4[[#This Row],[modelo_2]],Tabla4[[#This Row],[modelo_3]])
B13: =IF(Tabla4[[#This Row],[instructor_]]="","",_xlfn.XLOOKUP(Tabla4[[#This Row],[instructor_]],diccionario_!$A$1:$A$13,diccionario_!$B$1:$B$13,,0)) | C13: =IF(Tabla4[[#This Row],[instructor_]]="","",_xlfn.XLOOKUP(Tabla4[[#This Row],[instructor_]],diccionario_!$A$1:$A$13,diccionario_!$C$1:$C$13,,0)) | G13: =IF(Tabla4[[#This Row],[trabajador_]]="","",_xlfn.XLOOKUP(Tabla4[[#This Row],[trabajador_]],Tabla2[Nombre Completo],Tabla2[Número de Documento],,0)) | M13: =_xlfn.TEXTJOIN(" - ",TRUE,Tabla4[[#This Row],[modelo_1]],Tabla4[[#This Row],[modelo_2]],Tabla4[[#This Row],[modelo_3]])
... B41: =IF(Tabla4[[#This Row],[instructor_]]="","",_xlfn.XLOOKUP(Tabla4[[#This Row],[instructor_]],diccionario_!$A$1:$A$13,diccionario_!$B$1:$B$13,,0)) | C41: =IF(Tabla4[[#This Row],[instructor_]]="","",_xlfn.XLOOKUP(Tabla4[[#This Row],[instructor_]],diccionario_!$A$1:$A$13,diccionario_!$C$1:$C$13,,0)) | G41: =IF(Tabla4[[#This Row],[trabajador_]]="","",_xlfn.XLOOKUP(Tabla4[[#This Row],[trabajador_]],Tabla2[Nombre Completo],Tabla2[Número de Documento],,0)) | M41: =_xlfn.TEXTJOIN(" - ",TRUE,Tabla4[[#This Row],[modelo_1]],Tabla4[[#This Row],[modelo_2]],Tabla4[[#This Row],[modelo_3]])

Sheet bbdd
A1: correlativo_ | B1: instructor_2 | C1: rut_instructor | D1: codigo_perfil_cv | E1: fecha | F1: hora | G1: trabajador_ | H1: rut_trabajador | I1: marca_ | J1: tipo_1 | K1: modelo_1 | L1: modelo_2 | M1: modelo_3 | N1: modelos_todos | O1: evaluacion_ | P1: estado_certificado | Q1: autorizado_para_operar | R1: codigo_ | S1: folio_ | T1: fecha_texto | U1: firma_ | V1: calificacion_ | W1: fecha_firma2
A2: 721 | B2: Marcelo Camilo Barrera Acevedo | C2: 13.364.290-0 | D2: P-8549-2359-004-V01 | E2: 46042 | F2: 0.51388889 | G2: Vargas Castañeda Daniel Damian | H2: 12.041.212-4 | I2: MERCEDES BENZ | J2: MINIBUS | K2: SPRINTER 315 – 415 – 515 – 517 4X2 | N2: SPRINTER 315 – 415 – 515 – 517 4X2 | O2: 1 | P2: Generado | Q2: =IF(Tabla1[[#This Row],[evaluacion_]]="","",IF(Tabla1[[#This Row],[evaluacion_]]=1,"Habilitado","No Habilitado")) -> Habilitado | R2: =IF(Tabla1[[#This Row],[fecha]]="","",TEXT(Tabla1[[#This Row],[fecha]],"DMMAAAA")&TEXT(Tabla1[[#This Row],[hora]],"HHmm")) -> 200120261220 | S2: =_xlfn.CONCAT(Tabla1[[#This Row],[codigo_]],Tabla1[[#This Row],[correlativo_]]) -> 200120261220721 | T2: =DAY(E2) & " de " & TEXT(E2, "mmmm") & " del " & YEAR(E2) -> 20 de enero del 2026 | U2: =_xlfn.XLOOKUP(Tabla1[[#This Row],[instructor_2]],diccionario_!$A$1:$A$11,diccionario_!$D$1:$D$11,,0) -> Marcelo Barrera A. | V2: =TEXT(O2,"0%") -> 100% | W2: 20 de enero del 2026 a las 12:40
A3: 722 | B3: Marcelo Camilo Barrera Acevedo | C3: 13.364.290-0 | D3: P-8549-2359-004-V01 | E3: 46043 | F3: 0.74305556 | G3: Reyes Rojas Paloma Carolina | H3: 19.966.551-0 | I3: MERCEDES BENZ | J3: MINIBUS | K3: SPRINTER 315 – 415 – 515 – 517 4X2 | N3: SPRINTER 315 – 415 – 515 – 517 4X2 | O3: 1 | P3: Generado | Q3: =IF(Tabla1[[#This Row],[evaluacion_]]="","",IF(Tabla1[[#This Row],[evaluacion_]]=1,"Habilitado","No Habilitado")) -> Habilitado | R3: =IF(Tabla1[[#This Row],[fecha]]="","",TEXT(Tabla1[[#This Row],[fecha]],"DMMAAAA")&TEXT(Tabla1[[#This Row],[hora]],"HHmm")) -> 210120261750 | S3: =_xlfn.CONCAT(Tabla1[[#This Row],[codigo_]],Tabla1[[#This Row],[correlativo_]]) -> 210120261750722 | T3: =DAY(E3) & " de " & TEXT(E3, "mmmm") & " del " & YEAR(E3) -> 21 de enero del 2026 | U3: =_xlfn.XLOOKUP(Tabla1[[#This Row],[instructor_2]],diccionario_!$A$1:$A$11,diccionario_!$D$1:$D$11,,0) -> Marcelo Barrera A. | V3: =TEXT(O3,"0%") -> 100% | W3: 21 de enero del 2026 a las 17:56
A4: 723 | B4: Marcelo Camilo Barrera Acevedo | C4: 13.364.290-0 | D4: P-8549-2359-004-V01 | E4: 46044 | F4: 0.67708333 | G4: Rojas Perez Carlos Mauricio | H4: 12.876.938-2 | I4: MERCEDES BENZ | J4: BUS 1 PISO | K4: O500 RS - OC500 RF | N4: O500 RS - OC500 RF | O4: 1 | P4: Generado | Q4: =IF(Tabla1[[#This Row],[evaluacion_]]="","",IF(Tabla1[[#This Row],[evaluacion_]]=1,"Habilitado","No Habilitado")) -> Habilitado | R4: =IF(Tabla1[[#This Row],[fecha]]="","",TEXT(Tabla1[[#This Row],[fecha]],"DMMAAAA")&TEXT(Tabla1[[#This Row],[hora]],"HHmm")) -> 220120261615 | S4: =_xlfn.CONCAT(Tabla1[[#This Row],[codigo_]],Tabla1[[#This Row],[correlativo_]]) -> 220120261615723 | T4: =DAY(E4) & " de " & TEXT(E4, "mmmm") & " del " & YEAR(E4) -> 22 de enero del 2026 | U4: =_xlfn.XLOOKUP(Tabla1[[#This Row],[instructor_2]],diccionario_!$A$1:$A$11,diccionario_!$D$1:$D$11,,0) -> Marcelo Barrera A. | V4: =TEXT(O4,"0%") -> 100% | W4: 22 de enero del 2026 a las 16:18
A5: 724 | B5: Marcelo Camilo Barrera Acevedo | C5: 13.364.290-0 | D5: P-8549-2359-004-V01 | E5: 46044 | F5: 0.67361111 | G5: Rojas Perez Carlos Mauricio | H5: 12.876.938-2 | I5: ZHONG TONG | J5: BUS 1 PISO | K5: ZT LCK6129EV | N5: ZT LCK6129EV | O5: 1 | P5: Generado | Q5: =IF(Tabla1[[#This Row],[evaluacion_]]="","",IF(Tabla1[[#This Row],[evaluacion_]]=1,"Habilitado","No Habilitado")) -> Habilitado | R5: =IF(Tabla1[[#This Row],[fecha]]="","",TEXT(Tabla1[[#This Row],[fecha]],"DMMAAAA")&TEXT(Tabla1[[#This Row],[hora]],"HHmm")) -> 220120261610 | S5: =_xlfn.CONCAT(Tabla1[[#This Row],[codigo_]],Tabla1[[#This Row],[correlativo_]]) -> 220120261610724 | T5: =DAY(E5) & " de " & TEXT(E5, "mmmm") & " del " & YEAR(E5) -> 22 de enero del 2026 | U5: =_xlfn.XLOOKUP(Tabla1[[#This Row],[instructor_2]],diccionario_!$A$1:$A$11,diccionario_!$D$1:$D$11,,0) -> Marcelo Barrera A. | V5: =TEXT(O5,"0%") -> 100% | W5: 22 de enero del 2026 a las 16:18
A6: 725 | B6: Marcelo Camilo Barrera Acevedo | C6: 13.364.290-0 | D6: P-8549-2359-004-V01 | E6: 46043 | F6: 0.67847222 | G6: Rojas Perez Carlos Mauricio | H6: 12.876.938-2 | I6: MERCEDES BENZ | J6: MINIBUS | K6: SPRINTER 315 – 415 – 515 – 517 4X2 | N6: SPRINTER 315 – 415 – 515 – 517 4X2 | O6: 1 | P6: Generado | Q6: =IF(Tabla1[[#This Row],[evaluacion_]]="","",IF(Tabla1[[#This Row],[evaluacion_]]=1,"Habilitado","No Habilitado")) -> Habilitado | R6: =IF(Tabla1[[#This Row],[fecha]]="","",TEXT(Tabla1[[#This Row],[fecha]],"DMMAAAA")&TEXT(Tabla1[[#This Row],[hora]],"HHmm")) -> 210120261617 | S6: =_xlfn.CONCAT(Tabla1[[#This Row],[codigo_]],Tabla1[[#This Row],[correlativo_]]) -> 210120261617725 | T6: =DAY(E6) & " de " & TEXT(E6, "mmmm") & " del " & YEAR(E6) -> 21 de enero del 2026 | U6: =_xlfn.XLOOKUP(Tabla1[[#This Row],[instructor_2]],diccionario_!$A$1:$A$11,diccionario_!$D$1:$D$11,,0) -> Marcelo Barrera A. | V6: =TEXT(O6,"0%") -> 100% | W6: 22 de enero del 2026 a las 16:18
A7: 726 | B7: Milla Miranda Guillermo Andres | C7: 15.325.100-2 | D7: P-8549-2359-004-V01 | E7: 46038 | F7: 0.375 | O7: información de calificación errónea | P7: Generado | Q7: =IF(Tabla1[[#This Row],[evaluacion_]]="","",IF(Tabla1[[#This Row],[evaluacion_]]=1,"Habilitado","No Habilitado")) -> No Habilitado | R7: =IF(Tabla1[[#This Row],[fecha]]="","",TEXT(Tabla1[[#This Row],[fecha]],"DMMAAAA")&TEXT(Tabla1[[#This Row],[hora]],"HHmm")) -> 160120260900 | S7: =_xlfn.CONCAT(Tabla1[[#This Row],[codigo_]],Tabla1[[#This Row],[correlativo_]]) -> 160120260900726 | T7: =DAY(E7) & " de " & TEXT(E7, "mmmm") & " del " & YEAR(E7) -> 16 de enero del 2026 | U7: =_xlfn.XLOOKUP(Tabla1[[#This Row],[instructor_2]],diccionario_!$A$1:$A$11,diccionario_!$D$1:$D$11,,0) -> Guillermo Milla M. | V7: =TEXT(O7,"0%") -> información de calificación errónea | W7: 27 de enero del 2026 a las 08:51
A8: 727 | B8: Gilberto Leonardo Urtubia Carvajal | C8: 9.249.626-0 | D8: P-8549-2359-004-V01 | E8: 46048 | F8: 0.625 | G8: Villanueva Donoso Leonardo Felipe | H8: 17.300.054-5 | I8: MERCEDES BENZ | J8: BUS 1 PISO | K8: O500 RS - OC500 RF | L8: LO915 - LO916 | N8: O500 RS - OC500 RF - LO915 - LO916 | O8: 1 | P8: Generado | Q8: =IF(Tabla1[[#This Row],[evaluacion_]]="","",IF(Tabla1[[#This Row],[evaluacion_]]=1,"Habilitado","No Habilitado")) -> Habilitado | R8: =IF(Tabla1[[#This Row],[fecha]]="","",TEXT(Tabla1[[#This Row],[fecha]],"DMMAAAA")&TEXT(Tabla1[[#This Row],[hora]],"HHmm")) -> 260120261500 | S8: =_xlfn.CONCAT(Tabla1[[#This Row],[codigo_]],Tabla1[[#This Row],[correlativo_]]) -> 260120261500727 | T8: =DAY(E8) & " de " & TEXT(E8, "mmmm") & " del " & YEAR(E8) -> 26 de enero del 2026 | U8: =_xlfn.XLOOKUP(Tabla1[[#This Row],[instructor_2]],diccionario_!$A$1:$A$11,diccionario_!$D$1:$D$11,,0) -> Gilerto Urtubia C. | V8: =TEXT(O8,"0%") -> 100% | W8: 27 de enero del 2026 a las 09:10
A9: 728 | B9: Gilberto Leonardo Urtubia Carvajal | C9: 9.249.626-0 | D9: P-8549-2359-004-V01 | E9: 46048 | F9: 0.75 | G9: Herrera Bustos Waldo Andrés | H9: 18.259.209-9 | I9: MERCEDES BENZ | J9: BUS 1 PISO | K9: O500 RS - OC500 RF | L9: LO915 - LO916 | N9: O500 RS - OC500 RF - LO915 - LO916 | O9: 1 | P9: Generado | Q9: =IF(Tabla1[[#This Row],[evaluacion_]]="","",IF(Tabla1[[#This Row],[evaluacion_]]=1,"Habilitado","No Habilitado")) -> Habilitado | R9: =IF(Tabla1[[#This Row],[fecha]]="","",TEXT(Tabla1[[#This Row],[fecha]],"DMMAAAA")&TEXT(Tabla1[[#This Row],[hora]],"HHmm")) -> 260120261800 | S9: =_xlfn.CONCAT(Tabla1[[#This Row],[codigo_]],Tabla1[[#This Row],[correlativo_]]) -> 260120261800728 | T9: =DAY(E9) & " de " & TEXT(E9, "mmmm") & " del " & YEAR(E9) -> 26 de enero del 2026 | U9: =_xlfn.XLOOKUP(Tabla1[[#This Row],[instructor_2]],diccionario_!$A$1:$A$11,diccionario_!$D$1:$D$11,,0) -> Gilerto Urtubia C. | V9: =TEXT(O9,"0%") -> 100% | W9: 27 de enero del 2026 a las 09:10
A10: 729 | B10: Daniel Rodrigo Carvajal Bucarey | C10: 10.528.715-1 | D10: P-8549-2359-004-V01 | E10: 46027 | F10: 0.625 | G10: Barrera Acevedo Marcelo Camilo | H10: 13.364.290-0 | I10: MERCEDES BENZ | J10: TAXIBUS | K10: LO915 - LO916 | N10: LO915 - LO916 | O10: 1 | P10: Generado | Q10: =IF(Tabla1[[#This Row],[evaluacion_]]="","",IF(Tabla1[[#This Row],[evaluacion_]]=1,"Habilitado","No Habilitado")) -> Habilitado | R10: =IF(Tabla1[[#This Row],[fecha]]="","",TEXT(Tabla1[[#This Row],[fecha]],"DMMAAAA")&TEXT(Tabla1[[#This Row],[hora]],"HHmm")) -> 50120261500 | S10: =_xlfn.CONCAT(Tabla1[[#This Row],[codigo_]],Tabla1[[#This Row],[correlativo_]]) -> 50120261500729 | T10: =DAY(E10) & " de " & TEXT(E10, "mmmm") & " del " & YEAR(E10) -> 5 de enero del 2026 | U10: =_xlfn.XLOOKUP(Tabla1[[#This Row],[instructor_2]],diccionario_!$A$1:$A$11,diccionario_!$D$1:$D$11,,0) -> Daniel Carvajal B. | V10: =TEXT(O10,"0%") -> 100% | W10: 27 de enero del 2026 a las 09:15
A11: 730 | B11: Daniel Rodrigo Carvajal Bucarey | C11: 10.528.715-1 | D11: P-8549-2359-004-V01 | E11: 46028 | F11: 0.66666667 | G11: Barrera Acevedo Marcelo Camilo | H11: 13.364.290-0 | I11: MERCEDES BENZ | J11: MINIBUS | K11: SPRINTER 315 – 415 – 515 – 517 4X2 | N11: SPRINTER 315 – 415 – 515 – 517 4X2 | O11: 1 | P11: Generado | Q11: =IF(Tabla1[[#This Row],[evaluacion_]]="","",IF(Tabla1[[#This Row],[evaluacion_]]=1,"Habilitado","No Habilitado")) -> Habilitado | R11: =IF(Tabla1[[#This Row],[fecha]]="","",TEXT(Tabla1[[#This Row],[fecha]],"DMMAAAA")&TEXT(Tabla1[[#This Row],[hora]],"HHmm")) -> 60120261600 | S11: =_xlfn.CONCAT(Tabla1[[#This Row],[codigo_]],Tabla1[[#This Row],[correlativo_]]) -> 60120261600730 | T11: =DAY(E11) & " de " & TEXT(E11, "mmmm") & " del " & YEAR(E11) -> 6 de enero del 2026 | U11: =_xlfn.XLOOKUP(Tabla1[[#This Row],[instructor_2]],diccionario_!$A$1:$A$11,diccionario_!$D$1:$D$11,,0) -> Daniel Carvajal B. | V11: =TEXT(O11,"0%") -> 100% | W11: 27 de enero del 2026 a las 09:15
A12: 731 | B12: Daniel Rodrigo Carvajal Bucarey | C12: 10.528.715-1 | D12: P-8549-2359-004-V01 | E12: 46028 | F12: 0.66666667 | G12: Barrera Acevedo Marcelo Camilo | H12: 13.364.290-0 | I12: MERCEDES BENZ | J12: BUS 1 PISO | K12: O500 RS - OC500 RF | N12: O500 RS - OC500 RF | O12: 1 | P12: Generado | Q12: =IF(Tabla1[[#This Row],[evaluacion_]]="","",IF(Tabla1[[#This Row],[evaluacion_]]=1,"Habilitado","No Habilitado")) -> Habilitado | R12: =IF(Tabla1[[#This Row],[fecha]]="","",TEXT(Tabla1[[#This Row],[fecha]],"DMMAAAA")&TEXT(Tabla1[[#This Row],[hora]],"HHmm")) -> 60120261600 | S12: =_xlfn.CONCAT(Tabla1[[#This Row],[codigo_]],Tabla1[[#This Row],[correlativo_]]) -> 60120261600731 | T12: =DAY(E12) & " de " & TEXT(E12, "mmmm") & " del " & YEAR(E12) -> 6 de enero del 2026 | U12: =_xlfn.XLOOKUP(Tabla1[[#This Row],[instructor_2]],diccionario_!$A$1:$A$11,diccionario_!$D$1:$D$11,,0) -> Daniel Carvajal B. | V12: =TEXT(O12,"0%") -> 100% | W12: 27 de enero del 2026 a las 09:15
A13: 732 | B13: Daniel Rodrigo Carvajal Bucarey | C13: 10.528.715-1 | D13: P-8549-2359-004-V01 | E13: 46028 | F13: 0.75 | G13: Barrera Acevedo Marcelo Camilo | H13: 13.364.290-0 | I13: ZHONG TONG | J13: BUS 1 PISO | K13: ZT LCK6129EV | N13: ZT LCK6129EV | O13: 1 | P13: Generado | Q13: =IF(Tabla1[[#This Row],[evaluacion_]]="","",IF(Tabla1[[#This Row],[evaluacion_]]=1,"Habilitado","No Habilitado")) -> Habilitado | R13: =IF(Tabla1[[#This Row],[fecha]]="","",TEXT(Tabla1[[#This Row],[fecha]],"DMMAAAA")&TEXT(Tabla1[[#This Row],[hora]],"HHmm")) -> 60120261800 | S13: =_xlfn.CONCAT(Tabla1[[#This Row],[codigo_]],Tabla1[[#This Row],[correlativo_]]) -> 60120261800732 | T13: =DAY(E13) & " de " & TEXT(E13, "mmmm") & " del " & YEAR(E13) -> 6 de enero del 2026 | U13: =_xlfn.XLOOKUP(Tabla1[[#This Row],[instructor_2]],diccionario_!$A$1:$A$11,diccionario_!$D$1:$D$11,,0) -> Daniel Carvajal B. | V13: =TEXT(O13,"0%") -> 100% | W13: 27 de enero del 2026 a las 09:15
A14: 733 | B14: Daniel Rodrigo Carvajal Bucarey | C14: 10.528.715-1 | D14: P-8549-2359-004-V01 | E14: 46029 | F14: 0.75 | G14: Barrera Acevedo Marcelo Camilo | H14: 13.364.290-0 | I14: SCANIA | J14: BUS 1 PISO | K14: K 360 IB | N14: K 360 IB | O14: información de calificación errónea | P14: Generado | Q14: =IF(Tabla1[[#This Row],[evaluacion_]]="","",IF(Tabla1[[#This Row],[evaluacion_]]=1,"Habilitado","No Habilitado")) -> No Habilitado | R14: =IF(Tabla1[[#This Row],[fecha]]="","",TEXT(Tabla1[[#This Row],[fecha]],"DMMAAAA")&TEXT(Tabla1[[#This Row],[hora]],"HHmm")) -> 70120261800 | S14: =_xlfn.CONCAT(Tabla1[[#This Row],[codigo_]],Tabla1[[#This Row],[correlativo_]]) -> 70120261800733 | T14: =DAY(E14) & " de " & TEXT(E14, "mmmm") & " del " & YEAR(E14) -> 7 de enero del 2026 | U14: =_xlfn.XLOOKUP(Tabla1[[#This Row],[instructor_2]],diccionario_!$A$1:$A$11,diccionario_!$D$1:$D$11,,0) -> Daniel Carvajal B. | V14: =TEXT(O14,"0%") -> información de calificación errónea | W14: 27 de enero del 2026 a las 09:15
A15: 734 | B15: Milla Miranda Guillermo Andres | C15: 15.325.100-2 | D15: P-8549-2359-004-V01 | E15: 46045 | F15: 0.75 | G15: Romero Palma Rodrigo Eugenio | H15: 12.774.701-6 | I15: MERCEDES BENZ | J15: BUS 1 PISO | K15: O500 RS - OC500 RF | L15: SPRINTER 315 – 415 – 515 – 517 4X2 | M15: SPRINTER 516 4x4 | N15: O500 RS - OC500 RF - SPRINTER 315 – 415 – 515 – 517 4X2 - SPRINTER 516 4x4 | O15: 1 | P15: Generado | Q15: =IF(Tabla1[[#This Row],[evaluacion_]]="","",IF(Tabla1[[#This Row],[evaluacion_]]=1,"Habilitado","No Habilitado")) -> Habilitado | R15: =IF(Tabla1[[#This Row],[fecha]]="","",TEXT(Tabla1[[#This Row],[fecha]],"DMMAAAA")&TEXT(Tabla1[[#This Row],[hora]],"HHmm")) -> 230120261800 | S15: =_xlfn.CONCAT(Tabla1[[#This Row],[codigo_]],Tabla1[[#This Row],[correlativo_]]) -> 230120261800734 | T15: =DAY(E15) & " de " & TEXT(E15, "mmmm") & " del " & YEAR(E15) -> 23 de enero del 2026 | U15: =_xlfn.XLOOKUP(Tabla1[[#This Row],[instructor_2]],diccionario_!$A$1:$A$11,diccionario_!$D$1:$D$11,,0) -> Guillermo Milla M. | V15: =TEXT(O15,"0%") -> 100% | W15: 27 de enero del 2026 a las 11:06
A16: 735 | B16: Milla Miranda Guillermo Andres | C16: 15.325.100-2 | D16: P-8549-2359-004-V01 | E16: 46045 | F16: 0.75 | G16: Romero Palma Rodrigo Eugenio | H16: 12.774.701-6 | I16: SCANIA | J16: BUS 1 PISO | K16: K 360 IB | N16: K 360 IB | O16: 1 | P16: Generado | Q16: =IF(Tabla1[[#This Row],[evaluacion_]]="","",IF(Tabla1[[#This Row],[evaluacion_]]=1,"Habilitado","No Habilitado")) -> Habilitado | R16: =IF(Tabla1[[#This Row],[fecha]]="","",TEXT(Tabla1[[#This Row],[fecha]],"DMMAAAA")&TEXT(Tabla1[[#This Row],[hora]],"HHmm")) -> 230120261800 | S16: =_xlfn.CONCAT(Tabla1[[#This Row],[codigo_]],Tabla1[[#This Row],[correlativo_]]) -> 230120261800735 | T16: =DAY(E16) & " de " & TEXT(E16, "mmmm") & " del " & YEAR(E16) -> 23 de enero del 2026 | U16: =_xlfn.XLOOKUP(Tabla1[[#This Row],[instructor_2]],diccionario_!$A$1:$A$11,diccionario_!$D$1:$D$11,,0) -> Guillermo Milla M. | V16: =TEXT(O16,"0%") -> 100% | W16: 27 de enero del 2026 a las 11:06
A17: 736 | B17: Milla Miranda Guillermo Andres | C17: 15.325.100-2 | D17: P-8549-2359-004-V01 | E17: 46045 | F17: 0.75 | G17: Romero Palma Rodrigo Eugenio | H17: 12.774.701-6 | I17: MERCEDES BENZ | J17: BUS 1 PISO | K17: O500 RS - OC500 RF | L17: SPRINTER 315 – 415 – 515 – 517 4X2 | M17: SPRINTER 516 4x4 | N17: O500 RS - OC500 RF - SPRINTER 315 – 415 – 515 – 517 4X2 - SPRINTER 516 4x4 | O17: 1 | P17: Generado | Q17: =IF(Tabla1[[#This Row],[evaluacion_]]="","",IF(Tabla1[[#This Row],[evaluacion_]]=1,"Habilitado","No Habilitado")) -> Habilitado | R17: =IF(Tabla1[[#This Row],[fecha]]="","",TEXT(Tabla1[[#This Row],[fecha]],"DMMAAAA")&TEXT(Tabla1[[#This Row],[hora]],"HHmm")) -> 230120261800 | S17: =_xlfn.CONCAT(Tabla1[[#This Row],[codigo_]],Tabla1[[#This Row],[correlativo_]]) -> 230120261800736 | T17: =DAY(E17) & " de " & TEXT(E17, "mmmm") & " del " & YEAR(E17) -> 23 de enero del 2026 | U17: =_xlfn.XLOOKUP(Tabla1[[#This Row],[instructor_2]],diccionario_!$A$1:$A$11,diccionario_!$D$1:$D$11,,0) -> Guillermo Milla M. | V17: =TEXT(O17,"0%") -> 100% | W17: 27 de enero del 2026 a las 11:20
A18: 737 | B18: Milla Miranda Guillermo Andres | C18: 15.325.100-2 | D18: P-8549-2359-004-V01 | E18: 46045 | F18: 0.75 | G18: Romero Palma Rodrigo Eugenio | H18: 12.774.701-6 | I18: SCANIA | J18: BUS 1 PISO | K18: K 360 IB | N18: K 360 IB | O18: 1 | P18: Generado | Q18: =IF(Tabla1[[#This Row],[evaluacion_]]="","",IF(Tabla1[[#This Row],[evaluacion_]]=1,"Habilitado","No Habilitado")) -> Habilitado | R18: =IF(Tabla1[[#This Row],[fecha]]="","",TEXT(Tabla1[[#This Row],[fecha]],"DMMAAAA")&TEXT(Tabla1[[#This Row],[hora]],"HHmm")) -> 230120261800 | S18: =_xlfn.CONCAT(Tabla1[[#This Row],[codigo_]],Tabla1[[#This Row],[correlativo_]]) -> 230120261800737 | T18: =DAY(E18) & " de " & TEXT(E18, "mmmm") & " del " & YEAR(E18) -> 23 de enero del 2026 | U18: =_xlfn.XLOOKUP(Tabla1[[#This Row],[instructor_2]],diccionario_!$A$1:$A$11,diccionario_!$D$1:$D$11,,0) -> Guillermo Milla M. | V18: =TEXT(O18,"0%") -> 100% | W18: 27 de enero del 2026 a las 11:21
A19: 738 | B19: Milla Miranda Guillermo Andres | C19: 15.325.100-2 | D19: P-8549-2359-004-V01 | E19: 46049 | F19: 0.4875 | G19: Villagran Latoja Thania Andrea | H19: 19.176.738-1 | I19: MERCEDES BENZ | J19: BUS 1 PISO | K19: O500 RS - OC500 RF | L19: O500 RS - OC500 RF | M19: O500 RS-D | N19: O500 RS - OC500 RF - O500 RS - OC500 RF - O500 RS-D | O19: 1 | P19: Generado | Q19: =IF(Tabla1[[#This Row],[evaluacion_]]="","",IF(Tabla1[[#This Row],[evaluacion_]]=1,"Habilitado","No Habilitado")) -> Habilitado | R19: =IF(Tabla1[[#This Row],[fecha]]="","",TEXT(Tabla1[[#This Row],[fecha]],"DMMAAAA")&TEXT(Tabla1[[#This Row],[hora]],"HHmm")) -> 270120261142 | S19: =_xlfn.CONCAT(Tabla1[[#This Row],[codigo_]],Tabla1[[#This Row],[correlativo_]]) -> 270120261142738 | T19: =DAY(E19) & " de " & TEXT(E19, "mmmm") & " del " & YEAR(E19) -> 27 de enero del 2026 | U19: =_xlfn.XLOOKUP(Tabla1[[#This Row],[instructor_2]],diccionario_!$A$1:$A$11,diccionario_!$D$1:$D$11,,0) -> Guillermo Milla M. | V19: =TEXT(O19,"0%") -> 100% | W19: 27 de enero del 2026 a las 11:43
A20: 739 | B20: Milla Miranda Guillermo Andres | C20: 15.325.100-2 | D20: P-8549-2359-004-V01 | E20: 46040 | F20: 0.41666667 | G20: Flores Contreras Rubén Darío | H20: 12.834.564-7 | I20: MERCEDES BENZ | J20: BUS 2 PISOS | K20: O500 RS - OC500 RF | L20: O500 RS-D | M20: SPRINTER 315 – 415 – 515 – 517 4X2 | N20: O500 RS - OC500 RF - O500 RS-D - SPRINTER 315 – 415 – 515 – 517 4X2 | O20: 1 | P20: Generado | Q20: =IF(Tabla1[[#This Row],[evaluacion_]]="","",IF(Tabla1[[#This Row],[evaluacion_]]=1,"Habilitado","No Habilitado")) -> Habilitado | R20: =IF(Tabla1[[#This Row],[fecha]]="","",TEXT(Tabla1[[#This Row],[fecha]],"DMMAAAA")&TEXT(Tabla1[[#This Row],[hora]],"HHmm")) -> 180120261000 | S20: =_xlfn.CONCAT(Tabla1[[#This Row],[codigo_]],Tabla1[[#This Row],[correlativo_]]) -> 180120261000739 | T20: =DAY(E20) & " de " & TEXT(E20, "mmmm") & " del " & YEAR(E20) -> 18 de enero del 2026 | U20: =_xlfn.XLOOKUP(Tabla1[[#This Row],[instructor_2]],diccionario_!$A$1:$A$11,diccionario_!$D$1:$D$11,,0) -> Guillermo Milla M. | V20: =TEXT(O20,"0%") -> 100% | W20: 28 de enero del 2026 a las 08:39
A21: 740 | B21: Milla Miranda Guillermo Andres | C21: 15.325.100-2 | D21: P-8549-2359-004-V01 | E21: 46040 | F21: 0.41666667 | G21: Flores Contreras Rubén Darío | H21: 12.834.564-7 | I21: SCANIA | J21: BUS 2 PISOS | K21: K 360 IB | L21: K 400 IB | M21: K 440 IB | N21: K 360 IB - K 400 IB - K 440 IB | O21: 1 | P21: Generado | Q21: =IF(Tabla1[[#This Row],[evaluacion_]]="","",IF(Tabla1[[#This Row],[evaluacion_]]=1,"Habilitado","No Habilitado")) -> Habilitado | R21: =IF(Tabla1[[#This Row],[fecha]]="","",TEXT(Tabla1[[#This Row],[fecha]],"DMMAAAA")&TEXT(Tabla1[[#This Row],[hora]],"HHmm")) -> 180120261000 | S21: =_xlfn.CONCAT(Tabla1[[#This Row],[codigo_]],Tabla1[[#This Row],[correlativo_]]) -> 180120261000740 | T21: =DAY(E21) & " de " & TEXT(E21, "mmmm") & " del " & YEAR(E21) -> 18 de enero del 2026 | U21: =_xlfn.XLOOKUP(Tabla1[[#This Row],[instructor_2]],diccionario_!$A$1:$A$11,diccionario_!$D$1:$D$11,,0) -> Guillermo Milla M. | V21: =TEXT(O21,"0%") -> 100% | W21: 28 de enero del 2026 a las 08:39
A22: 741 | B22: Marcelo Camilo Barrera Acevedo | C22: 13.364.290-0 | D22: P-8549-2359-004-V01 | E22: 46040 | F22: 0.41666667 | G22: Flores Contreras Rubén Darío | H22: 12.834.564-7 | I22: VOLVO | J22: BUS 2 PISOS | K22: B 420R - B 430R | L22: B 450R | N22: B 420R - B 430R - B 450R | O22: 1 | P22: Generado | Q22: =IF(Tabla1[[#This Row],[evaluacion_]]="","",IF(Tabla1[[#This Row],[evaluacion_]]=1,"Habilitado","No Habilitado")) -> Habilitado | R22: =IF(Tabla1[[#This Row],[fecha]]="","",TEXT(Tabla1[[#This Row],[fecha]],"DMMAAAA")&TEXT(Tabla1[[#This Row],[hora]],"HHmm")) -> 180120261000 | S22: =_xlfn.CONCAT(Tabla1[[#This Row],[codigo_]],Tabla1[[#This Row],[correlativo_]]) -> 180120261000741 | T22: =DAY(E22) & " de " & TEXT(E22, "mmmm") & " del " & YEAR(E22) -> 18 de enero del 2026 | U22: =_xlfn.XLOOKUP(Tabla1[[#This Row],[instructor_2]],diccionario_!$A$1:$A$11,diccionario_!$D$1:$D$11,,0) -> Marcelo Barrera A. | V22: =TEXT(O22,"0%") -> 100% | W22: 28 de enero del 2026 a las 08:39
A23: 742 | B23: Gilberto Leonardo Urtubia Carvajal | C23: 9.249.626-0 | D23: P-8549-2359-004-V01 | E23: 46048 | F23: 0.70833333 | G23: Herrera Bustos Waldo Andrés | H23: 140000 | I23: MERCEDES BENZ | J23: MINIBUS | K23: SPRINTER 315 – 415 – 515 – 517 4X2 | N23: SPRINTER 315 – 415 – 515 – 517 4X2 | O23: 1 | P23: Generado | Q23: =IF(Tabla1[[#This Row],[evaluacion_]]="","",IF(Tabla1[[#This Row],[evaluacion_]]=1,"Habilitado","No Habilitado")) -> Habilitado | R23: =IF(Tabla1[[#This Row],[fecha]]="","",TEXT(Tabla1[[#This Row],[fecha]],"DMMAAAA")&TEXT(Tabla1[[#This Row],[hora]],"HHmm")) -> 260120261700 | S23: =_xlfn.CONCAT(Tabla1[[#This Row],[codigo_]],Tabla1[[#This Row],[correlativo_]]) -> 260120261700742 | T23: =DAY(E23) & " de " & TEXT(E23, "mmmm") & " del " & YEAR(E23) -> 26 de enero del 2026 | U23: =_xlfn.XLOOKUP(Tabla1[[#This Row],[instructor_2]],diccionario_!$A$1:$A$11,diccionario_!$D$1:$D$11,,0) -> Gilerto Urtubia C. | V23: =TEXT(O23,"0%") -> 100% | W23: 28 de enero del 2026 a las 16:40
A24: 743 | B24: Gilberto Leonardo Urtubia Carvajal | C24: 9.249.626-0 | D24: P-8549-2359-004-V01 | E24: 46048 | F24: 0.72916667 | G24: Villanueva Donoso Leonardo Felipe | H24: 17.300.054-5 | I24: MERCEDES BENZ | J24: MINIBUS | K24: SPRINTER 315 – 415 – 515 – 517 4X2 | N24: SPRINTER 315 – 415 – 515 – 517 4X2 | O24: 1 | P24: Generado | Q24: =IF(Tabla1[[#This Row],[evaluacion_]]="","",IF(Tabla1[[#This Row],[evaluacion_]]=1,"Habilitado","No Habilitado")) -> Habilitado | R24: =IF(Tabla1[[#This Row],[fecha]]="","",TEXT(Tabla1[[#This Row],[fecha]],"DMMAAAA")&TEXT(Tabla1[[#This Row],[hora]],"HHmm")) -> 260120261730 | S24: =_xlfn.CONCAT(Tabla1[[#This Row],[codigo_]],Tabla1[[#This Row],[correlativo_]]) -> 260120261730743 | T24: =DAY(E24) & " de " & TEXT(E24, "mmmm") & " del " & YEAR(E24) -> 26 de enero del 2026 | U24: =_xlfn.XLOOKUP(Tabla1[[#This Row],[instructor_2]],diccionario_!$A$1:$A$11,diccionario_!$D$1:$D$11,,0) -> Gilerto Urtubia C. | V24: =TEXT(O24,"0%") -> 100% | W24: 28 de enero del 2026 a las 16:40
A25: 744 | B25: Marcelo Camilo Barrera Acevedo | C25: 13.364.290-0 | D25: P-8549-2359-004-V01 | E25: 46051 | F25: 0.54166667 | G25: Barraza La Fuente Alejandro Marcelo | H25: 12.581.334-8 | I25: MERCEDES BENZ | J25: MINIBUS | K25: SPRINTER 315 – 415 – 515 – 517 4X2 | N25: SPRINTER 315 – 415 – 515 – 517 4X2 | O25: 1 | P25: Generado | Q25: =IF(Tabla1[[#This Row],[evaluacion_]]="","",IF(Tabla1[[#This Row],[evaluacion_]]=1,"Habilitado","No Habilitado")) -> Habilitado | R25: =IF(Tabla1[[#This Row],[fecha]]="","",TEXT(Tabla1[[#This Row],[fecha]],"DMMAAAA")&TEXT(Tabla1[[#This Row],[hora]],"HHmm")) -> 290120261300 | S25: =_xlfn.CONCAT(Tabla1[[#This Row],[codigo_]],Tabla1[[#This Row],[correlativo_]]) -> 290120261300744 | T25: =DAY(E25) & " de " & TEXT(E25, "mmmm") & " del " & YEAR(E25) -> 29 de enero del 2026 | U25: =_xlfn.XLOOKUP(Tabla1[[#This Row],[instructor_2]],diccionario_!$A$1:$A$11,diccionario_!$D$1:$D$11,,0) -> Marcelo Barrera A. | V25: =TEXT(O25,"0%") -> 100% | W25: 29 de enero del 2026 a las 13:28
A26: 745 | B26: Marcelo Camilo Barrera Acevedo | C26: 13.364.290-0 | D26: P-8549-2359-004-V01 | E26: 46051 | F26: 0.55902778 | G26: Valenzuela Lopez Waldo Elias | H26: 14.526.798-6 | I26: MERCEDES BENZ | J26: MINIBUS | K26: SPRINTER 315 – 415 – 515 – 517 4X2 | N26: SPRINTER 315 – 415 – 515 – 517 4X2 | O26: 1 | P26: Generado | Q26: =IF(Tabla1[[#This Row],[evaluacion_]]="","",IF(Tabla1[[#This Row],[evaluacion_]]=1,"Habilitado","No Habilitado")) -> Habilitado | R26: =IF(Tabla1[[#This Row],[fecha]]="","",TEXT(Tabla1[[#This Row],[fecha]],"DMMAAAA")&TEXT(Tabla1[[#This Row],[hora]],"HHmm")) -> 290120261325 | S26: =_xlfn.CONCAT(Tabla1[[#This Row],[codigo_]],Tabla1[[#This Row],[correlativo_]]) -> 290120261325745 | T26: =DAY(E26) & " de " & TEXT(E26, "mmmm") & " del " & YEAR(E26) -> 29 de enero del 2026 | U26: =_xlfn.XLOOKUP(Tabla1[[#This Row],[instructor_2]],diccionario_!$A$1:$A$11,diccionario_!$D$1:$D$11,,0) -> Marcelo Barrera A. | V26: =TEXT(O26,"0%") -> 100% | W26: 29 de enero del 2026 a las 13:28
A27: 746 | B27: Marcelo Camilo Barrera Acevedo | C27: 13.364.290-0 | D27: P-8549-2359-004-V01 | E27: 46058 | F27: 0.41666667 | G27: Molina Hidalgo Cristian Freddy | H27: 14.109.054-2 | I27: MERCEDES BENZ | J27: MINIBUS | K27: SPRINTER 315 – 415 – 515 – 517 4X2 | N27: SPRINTER 315 – 415 – 515 – 517 4X2 | O27: 1 | P27: Generado | Q27: =IF(Tabla1[[#This Row],[evaluacion_]]="","",IF(Tabla1[[#This Row],[evaluacion_]]=1,"Habilitado","No Habilitado")) -> Habilitado | R27: =IF(Tabla1[[#This Row],[fecha]]="","",TEXT(Tabla1[[#This Row],[fecha]],"DMMAAAA")&TEXT(Tabla1[[#This Row],[hora]],"HHmm")) -> 50220261000 | S27: =_xlfn.CONCAT(Tabla1[[#This Row],[codigo_]],Tabla1[[#This Row],[correlativo_]]) -> 50220261000746 | T27: =DAY(E27) & " de " & TEXT(E27, "mmmm") & " del " & YEAR(E27) -> 5 de febrero del 2026 | U27: =_xlfn.XLOOKUP(Tabla1[[#This Row],[instructor_2]],diccionario_!$A$1:$A$11,diccionario_!$D$1:$D$11,,0) -> Marcelo Barrera A. | V27: =TEXT(O27,"0%") -> 100% | W27: 5 de febrero del 2026 a las 10:08
A28: 747 | B28: Marcelo Camilo Barrera Acevedo | C28: 13.364.290-0 | D28: P-8549-2359-004-V01 | E28: 46064 | F28: 0.5 | G28: Sanquea Bahamondes Jaime Alberto | H28: 10.751.704-9 | I28: SCANIA | J28: BUS 1 PISO | K28: K 360 IB | N28: K 360 IB | O28: 1 | P28: Generado | Q28: =IF(Tabla1[[#This Row],[evaluacion_]]="","",IF(Tabla1[[#This Row],[evaluacion_]]=1,"Habilitado","No Habilitado")) -> Habilitado | R28: =IF(Tabla1[[#This Row],[fecha]]="","",TEXT(Tabla1[[#This Row],[fecha]],"DMMAAAA")&TEXT(Tabla1[[#This Row],[hora]],"HHmm")) -> 110220261200 | S28: =_xlfn.CONCAT(Tabla1[[#This Row],[codigo_]],Tabla1[[#This Row],[correlativo_]]) -> 110220261200747 | T28: =DAY(E28) & " de " & TEXT(E28, "mmmm") & " del " & YEAR(E28) -> 11 de febrero del 2026 | U28: =_xlfn.XLOOKUP(Tabla1[[#This Row],[instructor_2]],diccionario_!$A$1:$A$11,diccionario_!$D$1:$D$11,,0) -> Marcelo Barrera A. | V28: =TEXT(O28,"0%") -> 100% | W28: 11 de febrero del 2026 a las 12:18
A29: 748 | B29: Marcelo Camilo Barrera Acevedo | C29: 13.364.290-0 | D29: P-8549-2359-004-V01 | E29: 46064 | F29: 0.49305556 | G29: Sanquea Bahamondes Jaime Alberto | H29: 10.751.704-9 | I29: MERCEDES BENZ | J29: TAXIBUS | K29: LO915 - LO916 | L29: SPRINTER 315 – 415 – 515 – 517 4X2 | N29: LO915 - LO916 - SPRINTER 315 – 415 – 515 – 517 4X2 | O29: 1 | P29: Generado | Q29: =IF(Tabla1[[#This Row],[evaluacion_]]="","",IF(Tabla1[[#This Row],[evaluacion_]]=1,"Habilitado","No Habilitado")) -> Habilitado | R29: =IF(Tabla1[[#This Row],[fecha]]="","",TEXT(Tabla1[[#This Row],[fecha]],"DMMAAAA")&TEXT(Tabla1[[#This Row],[hora]],"HHmm")) -> 110220261150 | S29: =_xlfn.CONCAT(Tabla1[[#This Row],[codigo_]],Tabla1[[#This Row],[correlativo_]]) -> 110220261150748 | T29: =DAY(E29) & " de " & TEXT(E29, "mmmm") & " del " & YEAR(E29) -> 11 de febrero del 2026 | U29: =_xlfn.XLOOKUP(Tabla1[[#This Row],[instructor_2]],diccionario_!$A$1:$A$11,diccionario_!$D$1:$D$11,,0) -> Marcelo Barrera A. | V29: =TEXT(O29,"0%") -> 100% | W29: 11 de febrero del 2026 a las 12:18
A30: 749 | B30: Marcelo Camilo Barrera Acevedo | C30: 13.364.290-0 | D30: P-8549-2359-004-V01 | E30: 46063 | F30: 0.75 | G30: Sanquea Bahamondes Jaime Alberto | H30: 10.751.704-9 | I30: MERCEDES BENZ | J30: BUS 1 PISO | K30: O500 RS - OC500 RF | N30: O500 RS - OC500 RF | O30: 1 | P30: Generado | Q30: =IF(Tabla1[[#This Row],[evaluacion_]]="","",IF(Tabla1[[#This Row],[evaluacion_]]=1,"Habilitado","No Habilitado")) -> Habilitado | R30: =IF(Tabla1[[#This Row],[fecha]]="","",TEXT(Tabla1[[#This Row],[fecha]],"DMMAAAA")&TEXT(Tabla1[[#This Row],[hora]],"HHmm")) -> 100220261800 | S30: =_xlfn.CONCAT(Tabla1[[#This Row],[codigo_]],Tabla1[[#This Row],[correlativo_]]) -> 100220261800749 | T30: =DAY(E30) & " de " & TEXT(E30, "mmmm") & " del " & YEAR(E30) -> 10 de febrero del 2026 | U30: =_xlfn.XLOOKUP(Tabla1[[#This Row],[instructor_2]],diccionario_!$A$1:$A$11,diccionario_!$D$1:$D$11,,0) -> Marcelo Barrera A. | V30: =TEXT(O30,"0%") -> 100% | W30: 11 de febrero del 2026 a las 12:18
A31: 750 | O31: 1 | P31: Generado | Q31: =IF(Tabla1[[#This Row],[evaluacion_]]="","",IF(Tabla1[[#This Row],[evaluacion_]]=1,"Habilitado","No Habilitado")) -> Habilitado | R31: =IF(Tabla1[[#This Row],[fecha]]="","",TEXT(Tabla1[[#This Row],[fecha]],"DMMAAAA")&TEXT(Tabla1[[#This Row],[hora]],"HHmm")) | S31: =_xlfn.CONCAT(Tabla1[[#This Row],[codigo_]],Tabla1[[#This Row],[correlativo_]]) -> 750 | T31: =DAY(E31) & " de " & TEXT(E31, "mmmm") & " del " & YEAR(E31) -> 0 de enero del 1900 | U31: =_xlfn.XLOOKUP(Tabla1[[#This Row],[instructor_2]],diccionario_!$A$1:$A$11,diccionario_!$D$1:$D$11,,0) -> 0 | V31: =TEXT(O31,"0%") -> 100% | W31: 12 de febrero del 2026 a las 09:05
A32: 751 | B32: Daniel Rodrigo Carvajal Bucarey | C32: 10.528.715-1 | D32: P-8549-2359-004-V01 | E32: 45988 | F32: 0.71180556 | G32: Fredes Leguás Claudio Andrés | H32: 14.544.485-3 | I32: MERCEDES BENZ | J32: BUS 1 PISO | K32: O500 RS - OC500 RF | N32: O500 RS - OC500 RF | O32: 1 | P32: Generado | Q32: =IF(Tabla1[[#This Row],[evaluacion_]]="","",IF(Tabla1[[#This Row],[evaluacion_]]=1,"Habilitado","No Habilitado")) -> Habilitado | R32: =IF(Tabla1[[#This Row],[fecha]]="","",TEXT(Tabla1[[#This Row],[fecha]],"DMMAAAA")&TEXT(Tabla1[[#This Row],[hora]],"HHmm")) -> 271120251705 | S32: =_xlfn.CONCAT(Tabla1[[#This Row],[codigo_]],Tabla1[[#This Row],[correlativo_]]) -> 271120251705751 | T32: =DAY(E32) & " de " & TEXT(E32, "mmmm") & " del " & YEAR(E32) -> 27 de noviembre del 2025 | U32: =_xlfn.XLOOKUP(Tabla1[[#This Row],[instructor_2]],diccionario_!$A$1:$A$11,diccionario_!$D$1:$D$11,,0) -> Daniel Carvajal B. | V32: =TEXT(O32,"0%") -> 100% | W32: 12 de febrero del 2026 a las 09:05
A33: 752 | B33: Daniel Rodrigo Carvajal Bucarey | C33: 10.528.715-1 | D33: P-8549-2359-004-V01 | O33: información de calificación errónea | P33: Generado | Q33: =IF(Tabla1[[#This Row],[evaluacion_]]="","",IF(Tabla1[[#This Row],[evaluacion_]]=1,"Habilitado","No Habilitado")) -> No Habilitado | R33: =IF(Tabla1[[#This Row],[fecha]]="","",TEXT(Tabla1[[#This Row],[fecha]],"DMMAAAA")&TEXT(Tabla1[[#This Row],[hora]],"HHmm")) | S33: =_xlfn.CONCAT(Tabla1[[#This Row],[codigo_]],Tabla1[[#This Row],[correlativo_]]) -> 752 | T33: =DAY(E33) & " de " & TEXT(E33, "mmmm") & " del " & YEAR(E33) -> 0 de enero del 1900 | U33: =_xlfn.XLOOKUP(Tabla1[[#This Row],[instructor_2]],diccionario_!$A$1:$A$11,diccionario_!$D$1:$D$11,,0) -> Daniel Carvajal B. | V33: =TEXT(O33,"0%") -> información de calificación errónea | W33: 12 de febrero del 2026 a las 09:05
A34: 753 | B34: Daniel Rodrigo Carvajal Bucarey | C34: 10.528.715-1 | D34: P-8549-2359-004-V01 | E34: 45981 | F34: 0.72638889 | G34: Poblete Corvetto Danilo Eduardo | H34: 11.976.167-0 | I34: MERCEDES BENZ | J34: BUS 1 PISO | K34: O500 RS - OC500 RF | N34: O500 RS - OC500 RF | O34: 1 | P34: Generado | Q34: =IF(Tabla1[[#This Row],[evaluacion_]]="","",IF(Tabla1[[#This Row],[evaluacion_]]=1,"Habilitado","No Habilitado")) -> Habilitado | R34: =IF(Tabla1[[#This Row],[fecha]]="","",TEXT(Tabla1[[#This Row],[fecha]],"DMMAAAA")&TEXT(Tabla1[[#This Row],[hora]],"HHmm")) -> 201120251726 | S34: =_xlfn.CONCAT(Tabla1[[#This Row],[codigo_]],Tabla1[[#This Row],[correlativo_]]) -> 201120251726753 | T34: =DAY(E34) & " de " & TEXT(E34, "mmmm") & " del " & YEAR(E34) -> 20 de noviembre del 2025 | U34: =_xlfn.XLOOKUP(Tabla1[[#This Row],[instructor_2]],diccionario_!$A$1:$A$11,diccionario_!$D$1:$D$11,,0) -> Daniel Carvajal B. | V34: =TEXT(O34,"0%") -> 100% | W34: 12 de febrero del 2026 a las 09:13
A35: 754 | B35: Daniel Rodrigo Carvajal Bucarey | C35: 10.528.715-1 | D35: P-8549-2359-004-V01 | E35: 45988 | F35: 0.60416667 | G35: Flores Soza Alejandra Andrea | H35: 13.910.562-1 | I35: MERCEDES BENZ | J35: BUS 1 PISO | K35: O500 RS - OC500 RF | N35: O500 RS - OC500 RF | O35: 1 | P35: Generado | Q35: =IF(Tabla1[[#This Row],[evaluacion_]]="","",IF(Tabla1[[#This Row],[evaluacion_]]=1,"Habilitado","No Habilitado")) -> Habilitado | R35: =IF(Tabla1[[#This Row],[fecha]]="","",TEXT(Tabla1[[#This Row],[fecha]],"DMMAAAA")&TEXT(Tabla1[[#This Row],[hora]],"HHmm")) -> 271120251430 | S35: =_xlfn.CONCAT(Tabla1[[#This Row],[codigo_]],Tabla1[[#This Row],[correlativo_]]) -> 271120251430754 | T35: =DAY(E35) & " de " & TEXT(E35, "mmmm") & " del " & YEAR(E35) -> 27 de noviembre del 2025 | U35: =_xlfn.XLOOKUP(Tabla1[[#This Row],[instructor_2]],diccionario_!$A$1:$A$11,diccionario_!$D$1:$D$11,,0) -> Daniel Carvajal B. | V35: =TEXT(O35,"0%") -> 100% | W35: 12 de febrero del 2026 a las 09:18
A36: 755 | B36: Daniel Rodrigo Carvajal Bucarey | C36: 10.528.715-1 | D36: P-8549-2359-004-V01 | E36: 45988 | F36: 0.65694444 | G36: Novoa Diaz Juan Carlos | H36: 12.112.770-9 | I36: MERCEDES BENZ | J36: BUS 1 PISO | K36: O500 RS - OC500 RF | N36: O500 RS - OC500 RF | O36: 1 | P36: Generado | Q36: =IF(Tabla1[[#This Row],[evaluacion_]]="","",IF(Tabla1[[#This Row],[evaluacion_]]=1,"Habilitado","No Habilitado")) -> Habilitado | R36: =IF(Tabla1[[#This Row],[fecha]]="","",TEXT(Tabla1[[#This Row],[fecha]],"DMMAAAA")&TEXT(Tabla1[[#This Row],[hora]],"HHmm")) -> 271120251546 | S36: =_xlfn.CONCAT(Tabla1[[#This Row],[codigo_]],Tabla1[[#This Row],[correlativo_]]) -> 271120251546755 | T36: =DAY(E36) & " de " & TEXT(E36, "mmmm") & " del " & YEAR(E36) -> 27 de noviembre del 2025 | U36: =_xlfn.XLOOKUP(Tabla1[[#This Row],[instructor_2]],diccionario_!$A$1:$A$11,diccionario_!$D$1:$D$11,,0) -> Daniel Carvajal B. | V36: =TEXT(O36,"0%") -> 100% | W36: 12 de febrero del 2026 a las 09:28
A37: 756 | B37: Daniel Rodrigo Carvajal Bucarey | C37: 10.528.715-1 | D37: P-8549-2359-004-V01 | E37: 45988 | F37: 0.64166667 | G37: Lopez Guzman Edbel Gerardo | H37: 25.468.926-2 | I37: MERCEDES BENZ | J37: BUS 1 PISO | K37: O500 RS - OC500 RF | N37: O500 RS - OC500 RF | O37: 1 | P37: Generado | Q37: =IF(Tabla1[[#This Row],[evaluacion_]]="","",IF(Tabla1[[#This Row],[evaluacion_]]=1,"Habilitado","No Habilitado")) -> Habilitado | R37: =IF(Tabla1[[#This Row],[fecha]]="","",TEXT(Tabla1[[#This Row],[fecha]],"DMMAAAA")&TEXT(Tabla1[[#This Row],[hora]],"HHmm")) -> 271120251524 | S37: =_xlfn.CONCAT(Tabla1[[#This Row],[codigo_]],Tabla1[[#This Row],[correlativo_]]) -> 271120251524756 | T37: =DAY(E37) & " de " & TEXT(E37, "mmmm") & " del " & YEAR(E37) -> 27 de noviembre del 2025 | U37: =_xlfn.XLOOKUP(Tabla1[[#This Row],[instructor_2]],diccionario_!$A$1:$A$11,diccionario_!$D$1:$D$11,,0) -> Daniel Carvajal B. | V37: =TEXT(O37,"0%") -> 100% | W37: 12 de febrero del 2026 a las 09:33
A38: 757 | B38: Daniel Rodrigo Carvajal Bucarey | C38: 10.528.715-1 | D38: P-8549-2359-004-V01 | E38: 45988 | F38: 0.62152778 | G38: Cornejo Pino Miguel Ángel | H38: 10.396.058-4 | I38: MERCEDES BENZ | J38: BUS 1 PISO | K38: O500 RS - OC500 RF | N38: O500 RS - OC500 RF | O38: 1 | P38: Generado | Q38: =IF(Tabla1[[#This Row],[evaluacion_]]="","",IF(Tabla1[[#This Row],[evaluacion_]]=1,"Habilitado","No Habilitado")) -> Habilitado | R38: =IF(Tabla1[[#This Row],[fecha]]="","",TEXT(Tabla1[[#This Row],[fecha]],"DMMAAAA")&TEXT(Tabla1[[#This Row],[hora]],"HHmm")) -> 271120251455 | S38: =_xlfn.CONCAT(Tabla1[[#This Row],[codigo_]],Tabla1[[#This Row],[correlativo_]]) -> 271120251455757 | T38: =DAY(E38) & " de " & TEXT(E38, "mmmm") & " del " & YEAR(E38) -> 27 de noviembre del 2025 | U38: =_xlfn.XLOOKUP(Tabla1[[#This Row],[instructor_2]],diccionario_!$A$1:$A$11,diccionario_!$D$1:$D$11,,0) -> Daniel Carvajal B. | V38: =TEXT(O38,"0%") -> 100% | W38: 12 de febrero del 2026 a las 09:36
A39: 758 | B39: Daniel Rodrigo Carvajal Bucarey | C39: 10.528.715-1 | D39: P-8549-2359-004-V01 | E39: 46003 | F39: 0.69305556 | G39: Tejero Rocha Jimmy Alexander | H39: 28.093.659-6 | I39: MERCEDES BENZ | J39: BUS 1 PISO | K39: O500 RS - OC500 RF | N39: O500 RS - OC500 RF | O39: 1 | P39: Generado | Q39: =IF(Tabla1[[#This Row],[evaluacion_]]="","",IF(Tabla1[[#This Row],[evaluacion_]]=1,"Habilitado","No Habilitado")) -> Habilitado | R39: =IF(Tabla1[[#This Row],[fecha]]="","",TEXT(Tabla1[[#This Row],[fecha]],"DMMAAAA")&TEXT(Tabla1[[#This Row],[hora]],"HHmm")) -> 121220251638 | S39: =_xlfn.CONCAT(Tabla1[[#This Row],[codigo_]],Tabla1[[#This Row],[correlativo_]]) -> 121220251638758 | T39: =DAY(E39) & " de " & TEXT(E39, "mmmm") & " del " & YEAR(E39) -> 12 de diciembre del 2025 | U39: =_xlfn.XLOOKUP(Tabla1[[#This Row],[instructor_2]],diccionario_!$A$1:$A$11,diccionario_!$D$1:$D$11,,0) -> Daniel Carvajal B. | V39: =TEXT(O39,"0%") -> 100% | W39: 12 de febrero del 2026 a las 09:38
A40: 759 | B40: Daniel Rodrigo Carvajal Bucarey | C40: 10.528.715-1 | D40: P-8549-2359-004-V01 | E40: 46003 | F40: 0.75 | G40: Conde Forero Hermes Ivan | H40: 27.437.890-5 | I40: MERCEDES BENZ | J40: BUS 1 PISO | K40: O500 RS - OC500 RF | N40: O500 RS - OC500 RF | O40: 1 | P40: Generado | Q40: =IF(Tabla1[[#This Row],[evaluacion_]]="","",IF(Tabla1[[#This Row],[evaluacion_]]=1,"Habilitado","No Habilitado")) -> Habilitado | R40: =IF(Tabla1[[#This Row],[fecha]]="","",TEXT(Tabla1[[#This Row],[fecha]],"DMMAAAA")&TEXT(Tabla1[[#This Row],[hora]],"HHmm")) -> 121220251800 | S40: =_xlfn.CONCAT(Tabla1[[#This Row],[codigo_]],Tabla1[[#This Row],[correlativo_]]) -> 121220251800759 | T40: =DAY(E40) & " de " & TEXT(E40, "mmmm") & " del " & YEAR(E40) -> 12 de diciembre del 2025 | U40: =_xlfn.XLOOKUP(Tabla1[[#This Row],[instructor_2]],diccionario_!$A$1:$A$11,diccionario_!$D$1:$D$11,,0) -> Daniel Carvajal B. | V40: =TEXT(O40,"0%") -> 100% | W40: 12 de febrero del 2026 a las 09:39
...

Sheet Registro_
A1: correlativo_ | B1: instructor_2 | C1: rut_instructor | D1: codigo_perfil_cv | E1: fecha | F1: hora | G1: trabajador_ | H1: rut_trabajador | I1: marca_ | J1: tipo_1 | K1: modelo_1 | L1: modelo_2 | M1: modelo_3 | N1: modelos_todos | O1: evaluacion_ | P1: estado_certificado | Q1: autorizado_para_operar | R1: codigo_ | S1: folio_ | T1: fecha_texto | U1: firma_ | V1: calificacion_ | W1: fecha_firma2
A2: 16 | B2: Daniel Rodrigo Carvajal Bucarey | C2: 10.528.715-1 | D2: P-8549-2359-004-V01 | E2: 45844 | F2: 0.39583333 | G2: Gonzalez Miranda Amanda Raquel | H2: 14.561.027-3 | I2: ZHONG TONG | J2: BUS | K2: ZT LCK6129EV | N2: ZT LCK6129EV | O2: 1 | P2: generado | Q2: =IF(Tabla1[[#This Row],[evaluacion_]]="","",IF(Tabla1[[#This Row],[evaluacion_]]=1,"Habilitado","No Habilitado")) -> Habilitado | R2: =IF(Tabla1[[#This Row],[fecha]]="","",TEXT(Tabla1[[#This Row],[fecha]],"DMMAAAA")&TEXT(Tabla1[[#This Row],[hora]],"HHmm")) -> 200120261220 | S2: =_xlfn.CONCAT(Tabla1[[#This Row],[codigo_]],Tabla1[[#This Row],[correlativo_]]) -> 200120261220721 | T2: =DAY(E2) & " de " & TEXT(E2, "mmmm") & " del " & YEAR(E2) -> 6 de julio del 2025 | U2: =_xlfn.XLOOKUP(Tabla1[[#This Row],[instructor_2]],diccionario_!$A$1:$A$11,diccionario_!$D$1:$D$11,,0) -> Marcelo Barrera A. | V2: =TEXT(O2,"0%") -> 100% | W2: 11 de julio del 2025 a las 10:12
A3: 17 | B3: Daniel Rodrigo Carvajal Bucarey | C3: 10.528.715-1 | D3: P-8549-2359-004-V01 | E3: 45844 | F3: 0.39583333 | G3: Guaman Covarrubias Andres Elias | H3: 13.357.074-8 | I3: ZHONG TONG | J3: BUS | K3: ZT LCK6129EV | N3: ZT LCK6129EV | O3: 1 | P3: generado | Q3: =IF(Tabla1[[#This Row],[evaluacion_]]="","",IF(Tabla1[[#This Row],[evaluacion_]]=1,"Habilitado","No Habilitado")) -> Habilitado | R3: =IF(Tabla1[[#This Row],[fecha]]="","",TEXT(Tabla1[[#This Row],[fecha]],"DMMAAAA")&TEXT(Tabla1[[#This Row],[hora]],"HHmm")) -> 210120261750 | S3: =_xlfn.CONCAT(Tabla1[[#This Row],[codigo_]],Tabla1[[#This Row],[correlativo_]]) -> 210120261750722 | T3: =DAY(E3) & " de " & TEXT(E3, "mmmm") & " del " & YEAR(E3) -> 6 de julio del 2025 | U3: =_xlfn.XLOOKUP(Tabla1[[#This Row],[instructor_2]],diccionario_!$A$1:$A$11,diccionario_!$D$1:$D$11,,0) -> Marcelo Barrera A. | V3: =TEXT(O3,"0%") -> 100% | W3: 11 de julio del 2025 a las 10:12
A4: 18 | B4: Daniel Rodrigo Carvajal Bucarey | C4: 10.528.715-1 | D4: P-8549-2359-004-V01 | E4: 45844 | F4: 0.39583333 | G4: Lobos Delgado Frank Alexis | H4: 18.972.820-4 | I4: ZHONG TONG | J4: BUS | K4: ZT LCK6129EV | N4: ZT LCK6129EV | O4: 1 | P4: generado | Q4: =IF(Tabla1[[#This Row],[evaluacion_]]="","",IF(Tabla1[[#This Row],[evaluacion_]]=1,"Habilitado","No Habilitado")) -> Habilitado | R4: =IF(Tabla1[[#This Row],[fecha]]="","",TEXT(Tabla1[[#This Row],[fecha]],"DMMAAAA")&TEXT(Tabla1[[#This Row],[hora]],"HHmm")) -> 220120261615 | S4: =_xlfn.CONCAT(Tabla1[[#This Row],[codigo_]],Tabla1[[#This Row],[correlativo_]]) -> 220120261615723 | T4: =DAY(E4) & " de " & TEXT(E4, "mmmm") & " del " & YEAR(E4) -> 6 de julio del 2025 | U4: =_xlfn.XLOOKUP(Tabla1[[#This Row],[instructor_2]],diccionario_!$A$1:$A$11,diccionario_!$D$1:$D$11,,0) -> Marcelo Barrera A. | V4: =TEXT(O4,"0%") -> 100% | W4: 11 de julio del 2025 a las 10:12
A5: 19 | B5: Daniel Rodrigo Carvajal Bucarey | C5: 10.528.715-1 | D5: P-8549-2359-004-V01 | E5: 45844 | F5: 0.39583333 | G5: Madariaga Rodriguez Wilfredo Alberto | H5: 10.309.536-0 | I5: ZHONG TONG | J5: BUS | K5: ZT LCK6129EV | N5: ZT LCK6129EV | O5: 1 | P5: generado | Q5: =IF(Tabla1[[#This Row],[evaluacion_]]="","",IF(Tabla1[[#This Row],[evaluacion_]]=1,"Habilitado","No Habilitado")) -> Habilitado | R5: =IF(Tabla1[[#This Row],[fecha]]="","",TEXT(Tabla1[[#This Row],[fecha]],"DMMAAAA")&TEXT(Tabla1[[#This Row],[hora]],"HHmm")) -> 220120261610 | S5: =_xlfn.CONCAT(Tabla1[[#This Row],[codigo_]],Tabla1[[#This Row],[correlativo_]]) -> 220120261610724 | T5: =DAY(E5) & " de " & TEXT(E5, "mmmm") & " del " & YEAR(E5) -> 6 de julio del 2025 | U5: =_xlfn.XLOOKUP(Tabla1[[#This Row],[instructor_2]],diccionario_!$A$1:$A$11,diccionario_!$D$1:$D$11,,0) -> Marcelo Barrera A. | V5: =TEXT(O5,"0%") -> 100% | W5: 11 de julio del 2025 a las 10:12
A6: 20 | B6: Daniel Rodrigo Carvajal Bucarey | C6: 10.528.715-1 | D6: P-8549-2359-004-V01 | E6: 45844 | F6: 0.39583333 | G6: Molina Rocha Joiso Juan | H6: 8.907.872-5 | I6: ZHONG TONG | J6: BUS | K6: ZT LCK6129EV | N6: ZT LCK6129EV | O6: 1 | P6: generado | Q6: =IF(Tabla1[[#This Row],[evaluacion_]]="","",IF(Tabla1[[#This Row],[evaluacion_]]=1,"Habilitado","No Habilitado")) -> Habilitado | R6: =IF(Tabla1[[#This Row],[fecha]]="","",TEXT(Tabla1[[#This Row],[fecha]],"DMMAAAA")&TEXT(Tabla1[[#This Row],[hora]],"HHmm")) -> 210120261617 | S6: =_xlfn.CONCAT(Tabla1[[#This Row],[codigo_]],Tabla1[[#This Row],[correlativo_]]) -> 210120261617725 | T6: =DAY(E6) & " de " & TEXT(E6, "mmmm") & " del " & YEAR(E6) -> 6 de julio del 2025 | U6: =_xlfn.XLOOKUP(Tabla1[[#This Row],[instructor_2]],diccionario_!$A$1:$A$11,diccionario_!$D$1:$D$11,,0) -> Marcelo Barrera A. | V6: =TEXT(O6,"0%") -> 100% | W6: 11 de julio del 2025 a las 10:12
A7: 21 | B7: Daniel Rodrigo Carvajal Bucarey | C7: 10.528.715-1 | D7: P-8549-2359-004-V01 | E7: 45844 | F7: 0.39583333 | G7: Mondaca Muñoz Eduardo Antonio | H7: 14.622.667-1 | I7: ZHONG TONG | J7: BUS | K7: ZT LCK6129EV | N7: ZT LCK6129EV | O7: 1 | P7: generado | Q7: =IF(Tabla1[[#This Row],[evaluacion_]]="","",IF(Tabla1[[#This Row],[evaluacion_]]=1,"Habilitado","No Habilitado")) -> No Habilitado | R7: =IF(Tabla1[[#This Row],[fecha]]="","",TEXT(Tabla1[[#This Row],[fecha]],"DMMAAAA")&TEXT(Tabla1[[#This Row],[hora]],"HHmm")) -> 160120260900 | S7: =_xlfn.CONCAT(Tabla1[[#This Row],[codigo_]],Tabla1[[#This Row],[correlativo_]]) -> 160120260900726 | T7: =DAY(E7) & " de " & TEXT(E7, "mmmm") & " del " & YEAR(E7) -> 6 de julio del 2025 | U7: =_xlfn.XLOOKUP(Tabla1[[#This Row],[instructor_2]],diccionario_!$A$1:$A$11,diccionario_!$D$1:$D$11,,0) -> Guillermo Milla M. | V7: =TEXT(O7,"0%") -> 100% | W7: 11 de julio del 2025 a las 10:12
A8: 22 | B8: Daniel Rodrigo Carvajal Bucarey | C8: 10.528.715-1 | D8: P-8549-2359-004-V01 | E8: 45844 | F8: 0.39583333 | G8: Rivera Elgueta Silvia Del Rosario | H8: 10.117.619-3 | I8: ZHONG TONG | J8: BUS | K8: ZT LCK6129EV | N8: ZT LCK6129EV | O8: 1 | P8: generado | Q8: =IF(Tabla1[[#This Row],[evaluacion_]]="","",IF(Tabla1[[#This Row],[evaluacion_]]=1,"Habilitado","No Habilitado")) -> Habilitado | R8: =IF(Tabla1[[#This Row],[fecha]]="","",TEXT(Tabla1[[#This Row],[fecha]],"DMMAAAA")&TEXT(Tabla1[[#This Row],[hora]],"HHmm")) -> 260120261500 | S8: =_xlfn.CONCAT(Tabla1[[#This Row],[codigo_]],Tabla1[[#This Row],[correlativo_]]) -> 260120261500727 | T8: =DAY(E8) & " de " & TEXT(E8, "mmmm") & " del " & YEAR(E8) -> 6 de julio del 2025 | U8: =_xlfn.XLOOKUP(Tabla1[[#This Row],[instructor_2]],diccionario_!$A$1:$A$11,diccionario_!$D$1:$D$11,,0) -> Gilerto Urtubia C. | V8: =TEXT(O8,"0%") -> 100% | W8: 11 de julio del 2025 a las 10:12
A9: 23 | B9: Daniel Rodrigo Carvajal Bucarey | C9: 10.528.715-1 | D9: P-8549-2359-004-V01 | E9: 45844 | F9: 0.39583333 | G9: Rojas Marquez Carlos Alberto | H9: 25.445.393-5 | I9: ZHONG TONG | J9: BUS | K9: ZT LCK6129EV | N9: ZT LCK6129EV | O9: 1 | P9: generado | Q9: =IF(Tabla1[[#This Row],[evaluacion_]]="","",IF(Tabla1[[#This Row],[evaluacion_]]=1,"Habilitado","No Habilitado")) -> Habilitado | R9: =IF(Tabla1[[#This Row],[fecha]]="","",TEXT(Tabla1[[#This Row],[fecha]],"DMMAAAA")&TEXT(Tabla1[[#This Row],[hora]],"HHmm")) -> 260120261800 | S9: =_xlfn.CONCAT(Tabla1[[#This Row],[codigo_]],Tabla1[[#This Row],[correlativo_]]) -> 260120261800728 | T9: =DAY(E9) & " de " & TEXT(E9, "mmmm") & " del " & YEAR(E9) -> 6 de julio del 2025 | U9: =_xlfn.XLOOKUP(Tabla1[[#This Row],[instructor_2]],diccionario_!$A$1:$A$11,diccionario_!$D$1:$D$11,,0) -> Gilerto Urtubia C. | V9: =TEXT(O9,"0%") -> 100% | W9: 11 de julio del 2025 a las 10:12
A10: 24 | B10: Daniel Rodrigo Carvajal Bucarey | C10: 10.528.715-1 | D10: P-8549-2359-004-V01 | E10: 45844 | F10: 0.39583333 | G10: Salas Salgado Erwin Alejandro | H10: 14.333.830-4 | I10: ZHONG TONG | J10: BUS | K10: ZT LCK6129EV | N10: ZT LCK6129EV | O10: 1 | P10: generado | Q10: =IF(Tabla1[[#This Row],[evaluacion_]]="","",IF(Tabla1[[#This Row],[evaluacion_]]=1,"Habilitado","No Habilitado")) -> Habilitado | R10: =IF(Tabla1[[#This Row],[fecha]]="","",TEXT(Tabla1[[#This Row],[fecha]],"DMMAAAA")&TEXT(Tabla1[[#This Row],[hora]],"HHmm")) -> 50120261500 | S10: =_xlfn.CONCAT(Tabla1[[#This Row],[codigo_]],Tabla1[[#This Row],[correlativo_]]) -> 50120261500729 | T10: =DAY(E10) & " de " & TEXT(E10, "mmmm") & " del " & YEAR(E10) -> 6 de julio del 2025 | U10: =_xlfn.XLOOKUP(Tabla1[[#This Row],[instructor_2]],diccionario_!$A$1:$A$11,diccionario_!$D$1:$D$11,,0) -> Daniel Carvajal B. | V10: =TEXT(O10,"0%") -> 100% | W10: 11 de julio del 2025 a las 10:12
A11: 25 | B11: Daniel Rodrigo Carvajal Bucarey | C11: 10.528.715-1 | D11: P-8549-2359-004-V01 | E11: 45844 | F11: 0.39583333 | G11: Santibañez Pradenas Pedro Alfonso | H11: 9.724.427-8 | I11: ZHONG TONG | J11: BUS | K11: ZT LCK6129EV | N11: ZT LCK6129EV | O11: 1 | P11: generado | Q11: =IF(Tabla1[[#This Row],[evaluacion_]]="","",IF(Tabla1[[#This Row],[evaluacion_]]=1,"Habilitado","No Habilitado")) -> Habilitado | R11: =IF(Tabla1[[#This Row],[fecha]]="","",TEXT(Tabla1[[#This Row],[fecha]],"DMMAAAA")&TEXT(Tabla1[[#This Row],[hora]],"HHmm")) -> 60120261600 | S11: =_xlfn.CONCAT(Tabla1[[#This Row],[codigo_]],Tabla1[[#This Row],[correlativo_]]) -> 60120261600730 | T11: =DAY(E11) & " de " & TEXT(E11, "mmmm") & " del " & YEAR(E11) -> 6 de julio del 2025 | U11: =_xlfn.XLOOKUP(Tabla1[[#This Row],[instructor_2]],diccionario_!$A$1:$A$11,diccionario_!$D$1:$D$11,,0) -> Daniel Carvajal B. | V11: =TEXT(O11,"0%") -> 100% | W11: 11 de julio del 2025 a las 10:12
A12: 26 | B12: Daniel Rodrigo Carvajal Bucarey | C12: 10.528.715-1 | D12: P-8549-2359-004-V01 | E12: 45844 | F12: 0.39583333 | G12: Tapia Cortes Cristian Alejandro | H12: 15.013.992-9 | I12: ZHONG TONG | J12: BUS | K12: ZT LCK6129EV | N12: ZT LCK6129EV | O12: 1 | P12: generado | Q12: =IF(Tabla1[[#This Row],[evaluacion_]]="","",IF(Tabla1[[#This Row],[evaluacion_]]=1,"Habilitado","No Habilitado")) -> Habilitado | R12: =IF(Tabla1[[#This Row],[fecha]]="","",TEXT(Tabla1[[#This Row],[fecha]],"DMMAAAA")&TEXT(Tabla1[[#This Row],[hora]],"HHmm")) -> 60120261600 | S12: =_xlfn.CONCAT(Tabla1[[#This Row],[codigo_]],Tabla1[[#This Row],[correlativo_]]) -> 60120261600731 | T12: =DAY(E12) & " de " & TEXT(E12, "mmmm") & " del " & YEAR(E12) -> 6 de julio del 2025 | U12: =_xlfn.XLOOKUP(Tabla1[[#This Row],[instructor_2]],diccionario_!$A$1:$A$11,diccionario_!$D$1:$D$11,,0) -> Daniel Carvajal B. | V12: =TEXT(O12,"0%") -> 100% | W12: 11 de julio del 2025 a las 10:12
